<?xml version="1.0"?>
<robot xmlns:xacro="http://wiki.ros.org/xacro" name="my_gripper">
  <xacro:macro name="my_gripper" params="parent gripper_width:=0.02">

    <!-- 夾爪基座 -->
    <link name="gripper_base">
      <inertial>
        <origin xyz="0 0 0" rpy="0 0 0"/>
        <mass value="0.5"/>
        <inertia ixx="0.001" iyy="0.001" izz="0.001" ixy="0" ixz="0" iyz="0"/>
      </inertial>
      <visual>
        <origin xyz="0 0 0" rpy="0 0 0"/>
        <geometry>
          <box size="0.06 0.06 0.02"/>
        </geometry>
        <material name="gray">
          <color rgba="0.4 0.4 0.4 1.0"/>
        </material>
      </visual>
      <collision>
        <origin xyz="0 0 0" rpy="0 0 0"/>
        <geometry>
          <box size="0.06 0.06 0.02"/>
        </geometry>
      </collision>
    </link>

    <!-- 固定基座到機械手臂的工具端 (tool0) -->
    <joint name="gripper_base_fixed" type="fixed">
      <origin xyz="0 0 0" rpy="0 0 0"/>
      <parent link="${parent}"/>
      <child link="gripper_base"/>
    </joint>

    <!-- 左側夾指 -->
    <link name="left_finger">
      <inertial>
        <origin xyz="0 0 0" rpy="0 0 0"/>
        <mass value="0.1"/>
        <inertia ixx="0.0001" iyy="0.0001" izz="0.0001" ixy="0" ixz="0" iyz="0"/>
      </inertial>
      <visual>
        <origin xyz="0 0 0" rpy="0 0 0"/>
        <geometry>
          <box size="0.01 0.04 0.08"/>
        </geometry>
        <material name="silver">
          <color rgba="0.8 0.8 0.8 1.0"/>
        </material>
      </visual>
      <collision>
        <origin xyz="0 0 0" rpy="0 0 0"/>
        <geometry>
          <box size="0.01 0.04 0.08"/>
        </geometry>
      </collision>
    </link>

    <!-- 左夾指的 prismatic 關節 -->
    <joint name="left_finger_joint" type="prismatic">
      <origin xyz="0.03 0 0" rpy="0 0 0"/>
      <parent link="gripper_base"/>
      <child link="left_finger"/>
      <axis xyz="1 0 0"/>
      <limit lower="0.0" upper="${gripper_width}" effort="10" velocity="0.1"/>
      <command_interface name="position"/>
      <command_interface name="velocity"/>
      <state_interface name="position">
        <param name="initial_value">0.01</param> <!-- 讓夾爪有一個預設的開口 -->
      </state_interface>
      <state_interface name="velocity"/>
      <state_interface name="effort"/>
    </joint>

    <!-- 右側夾指 -->
    <link name="right_finger">
      <inertial>
        <origin xyz="0 0 0" rpy="0 0 0"/>
        <mass value="0.1"/>
        <inertia ixx="0.0001" iyy="0.0001" izz="0.0001" ixy="0" ixz="0" iyz="0"/>
      </inertial>
      <visual>
        <origin xyz="0 0 0" rpy="0 0 0"/>
        <geometry>
          <box size="0.01 0.04 0.08"/>
        </geometry>
        <material name="silver">
          <color rgba="0.8 0.8 0.8 1.0"/>
        </material>
      </visual>
      <collision>
        <origin xyz="0 0 0" rpy="0 0 0"/>
        <geometry>
          <box size="0.01 0.04 0.08"/>
        </geometry>
      </collision>
    </link>

    <!-- 右夾指的 prismatic 關節 -->
    <joint name="right_finger_joint" type="prismatic">
      <origin xyz="-0.03 0 0" rpy="0 0 0"/>
      <parent link="gripper_base"/>
      <child link="right_finger"/>
      <axis xyz="-1 0 0"/>
      <limit lower="0.0" upper="${gripper_width}" effort="10" velocity="0.1"/>
      <command_interface name="position"/>
      <command_interface name="velocity"/>
      <state_interface name="position">
        <param name="initial_value">0.01</param> <!-- 讓夾爪有一個預設的開口 -->
      </state_interface>
      <state_interface name="velocity"/>
      <state_interface name="effort"/>
    </joint>

  </xacro:macro>
</robot> 
